Workbook

Sheet Hallazgos
A1: Hallazgos principales – Resultados federales 2018-2024
A2: Cifras calculadas con los archivos del PREP de cada elección; ver hojas de detalle y Metodología.
A4: Cómo leer este archivo
A5: Todas las cifras salen de los archivos del PREP de cada elección (presidencia, diputaciones y senadurías 2018 y 2024; diputaciones 2021). Los porcentajes son sobre el total de votos emitidos. Hay dos lecturas: "bloques como compitieron" (la coalición de cada año tal cual) y "partidos" (el voto de coalición repartido entre sus partidos, para ver el crecimiento real de cada uno). Ver hoja Metodología.
A6: Nacional
A7: Presidencia: el bloque de Morena y aliados pasó de 53.2% (2018) a 59.8% (2024). Hay que tener en cuenta que sus integrantes cambian: PES en 2018, PVEM en 2021 y 2024.
A8: Diputaciones: el bloque de Morena y aliados pasó de 43.6% (2018) a 42.8% (2021), 54.7% (2024). Hay que tener en cuenta que sus integrantes cambian: PES en 2018, PVEM en 2021 y 2024.
A9: Senadurías: el bloque de Morena y aliados pasó de 43.7% (2018) a 55.1% (2024). Hay que tener en cuenta que sus integrantes cambian: PES en 2018, PVEM en 2021 y 2024.
A10: Presidencia: PAN + PRI + PRD sumados fueron 34.3% (2018), 27.5% (2024).
A11: Diputaciones: PAN + PRI + PRD sumados fueron 39.9% (2018), 39.6% (2021), 30.5% (2024).
A12: Senadurías: PAN + PRI + PRD sumados fueron 38.9% (2018), 30.0% (2024).
A13: MC creció en todos los cargos: diputaciones 4.3% (2018), 7.0% (2021), 10.9% (2024); presidencia 1.7% (2018), 10.3% (2024) (en 2018 MC iba con PAN y PRD, por eso su voto propio aparece bajo en la presidencia); senadurías 4.6% (2018), 10.9% (2024).
... A37: No se incluyen las diputaciones y senadurías de representación proporcional ni los cómputos oficiales. Los nombres de los bloques son una asignación mía a partir de las coaliciones de cada archivo. Al repartir el voto de coalición entre partidos se usa la regla de división en partes iguales con el residuo al partido con más votos propios en la casilla; es una aproximación, no el resultado oficial por partido.

Sheet Nacional
A1: Resumen nacional 2018-2024: presidencia, diputaciones y senadurías
A2: % sobre el total de votos emitidos, voto de coalición repartido entre sus partidos. Δ en puntos porcentuales (votos en cifras absolutas).
B4: Presidencia | D4: Diputaciones | G4: Senadurías | I4: Cambio
A5: Indicador | B5: 2018 | C5: 2024 | D5: 2018 | E5: 2021 | F5: 2024 | G5: 2018 | H5: 2024 | I5: Presidencia Δ 2024 vs 2018 | J5: Diputaciones Δ 2021 vs 2018 | K5: Diputaciones Δ 2024 vs 2021 | L5: Diputaciones Δ 2024 vs 2018 | M5: Senadurías Δ 2024 vs 2018
A6: Votos emitidos | B6: ='Base votos'!R36 -> 56611027 | C6: ='Base votos'!R69 -> 60115184 | D6: ='Base votos'!R102 -> 56300247 | E6: ='Base votos'!R135 -> 49151320 | F6: ='Base votos'!R168 -> 59466468 | G6: ='Base votos'!R201 -> 56691869 | H6: ='Base votos'!R234 -> 60003726 | I6: =C6-B6 -> 3504157 | J6: =E6-D6 -> -7148927 | K6: =F6-E6 -> 10315148 | L6: =F6-D6 -> 3166221 | M6: =H6-G6 -> 3311857
A7: Lista nominal (con dato) | B7: ='Base votos'!S36 -> 89129689 | C7: ='Base votos'!S69 -> 98468994 | D7: ='Base votos'!S102 -> 88948697 | E7: ='Base votos'!S135 -> 93328771 | F7: ='Base votos'!S168 -> 98214289 | G7: ='Base votos'!S201 -> 89127226 | H7: ='Base votos'!S234 -> 98438250 | I7: =C7-B7 -> 9339305 | J7: =E7-D7 -> 4380074 | K7: =F7-E7 -> 4885518 | L7: =F7-D7 -> 9265592 | M7: =H7-G7 -> 9311024
A8: Participación | B8: ='Base votos'!R36/'Base votos'!S36 -> 0.63515342 | C8: ='Base votos'!R69/'Base votos'!S69 -> 0.61049861 | D8: ='Base votos'!R102/'Base votos'!S102 -> 0.6329519 | E8: ='Base votos'!R135/'Base votos'!S135 -> 0.52664703 | F8: ='Base votos'!R168/'Base votos'!S168 -> 0.60547674 | G8: ='Base votos'!R201/'Base votos'!S201 -> 0.63607802 | H8: ='Base votos'!R234/'Base votos'!S234 -> 0.60955702 | I8: =(C8-B8)*100 -> -2.4654812 | J8: =(E8-D8)*100 -> -10.630487 | K8: =(F8-E8)*100 -> 7.8829715 | L8: =(F8-D8)*100 -> -2.7475158 | M8: =(H8-G8)*100 -> -2.6520998
A9: Votos nulos % | B9: ='Base votos'!Q36/'Base votos'!R36 -> 0.027752791 | C9: ='Base votos'!Q69/'Base votos'!R69 -> 0.023291021 | D9: ='Base votos'!Q102/'Base votos'!R102 -> 0.039833129 | E9: ='Base votos'!Q135/'Base votos'!R135 -> 0.034044294 | F9: ='Base votos'!Q168/'Base votos'!R168 -> 0.036825274 | G9: ='Base votos'!Q201/'Base votos'!R201 -> 0.041352614 | H9: ='Base votos'!Q234/'Base votos'!R234 -> 0.039496414 | I9: =(C9-B9)*100 -> -0.44617702 | J9: =(E9-D9)*100 -> -0.57888347 | K9: =(F9-E9)*100 -> 0.27809801 | L9: =(F9-D9)*100 -> -0.30078546 | M9: =(H9-G9)*100 -> -0.18562005
A10: Morena | B10: ='Base votos'!D36/'Base votos'!R36 -> 0.44775158 | C10: ='Base votos'!D69/'Base votos'!R69 -> 0.45814089 | D10: ='Base votos'!D102/'Base votos'!R102 -> 0.3749315 | E10: ='Base votos'!D135/'Base votos'!R135 -> 0.34177762 | F10: ='Base votos'!D168/'Base votos'!R168 -> 0.41080205 | G10: ='Base votos'!D201/'Base votos'!R201 -> 0.37744192 | H10: ='Base votos'!D234/'Base votos'!R234 -> 0.41006547 | I10: =(C10-B10)*100 -> 1.0389308 | J10: =(E10-D10)*100 -> -3.3153882 | K10: =(F10-E10)*100 -> 6.9024434 | L10: =(F10-D10)*100 -> 3.5870552 | M10: =(H10-G10)*100 -> 3.2623546
A11: PT | B11: ='Base votos'!E36/'Base votos'!R36 -> 0.058816103 | C11: ='Base votos'!E69/'Base votos'!R69 -> 0.062981193 | D11: ='Base votos'!E102/'Base votos'!R102 -> 0.038113616 | E11: ='Base votos'!E135/'Base votos'!R135 -> 0.03194429 | F11: ='Base votos'!E168/'Base votos'!R168 -> 0.053288082 | G11: ='Base votos'!E201/'Base votos'!R201 -> 0.037010546 | H11: ='Base votos'!E234/'Base votos'!R234 -> 0.05238283 | I11: =(C11-B11)*100 -> 0.41650898 | J11: =(E11-D11)*100 -> -0.61693265 | K11: =(F11-E11)*100 -> 2.1343792 | L11: =(F11-D11)*100 -> 1.5174466 | M11: =(H11-G11)*100 -> 1.5372285
A12: PVEM | B12: ='Base votos'!F36/'Base votos'!R36 -> 0.017705755 | C12: ='Base votos'!F69/'Base votos'!R69 -> 0.076472676 | D12: ='Base votos'!F102/'Base votos'!R102 -> 0.047504392 | E12: ='Base votos'!F135/'Base votos'!R135 -> 0.054053828 | F12: ='Base votos'!F168/'Base votos'!R168 -> 0.083025311 | G12: ='Base votos'!F201/'Base votos'!R201 -> 0.044190588 | H12: ='Base votos'!F234/'Base votos'!R234 -> 0.088477656 | I12: =(C12-B12)*100 -> 5.8766921 | J12: =(E12-D12)*100 -> 0.65494361 | K12: =(F12-E12)*100 -> 2.8971483 | L12: =(F12-D12)*100 -> 3.5520919 | M12: =(H12-G12)*100 -> 4.4287068
A13: PES | B13: ='Base votos'!G36/'Base votos'!R36 -> 0.025369015 | C13: ='Base votos'!G69/'Base votos'!R69 -> 0 | D13: ='Base votos'!G102/'Base votos'!R102 -> 0.02280141 | E13: ='Base votos'!G135/'Base votos'!R135 -> 0.027517959 | F13: ='Base votos'!G168/'Base votos'!R168 -> 0 | G13: ='Base votos'!G201/'Base votos'!R201 -> 0.022057713 | H13: ='Base votos'!G234/'Base votos'!R234 -> 0 | I13: =(C13-B13)*100 -> -2.5369015 | J13: =(E13-D13)*100 -> 0.47165491 | K13: =(F13-E13)*100 -> -2.7517959 | L13: =(F13-D13)*100 -> -2.280141 | M13: =(H13-G13)*100 -> -2.2057713
A14: PAN | B14: ='Base votos'!H36/'Base votos'!R36 -> 0.17843084 | C14: ='Base votos'!H69/'Base votos'!R69 -> 0.16161676 | D14: ='Base votos'!H102/'Base votos'!R102 -> 0.18044177 | E14: ='Base votos'!H135/'Base votos'!R135 -> 0.18268376 | F14: ='Base votos'!H168/'Base votos'!R168 -> 0.16994463 | G14: ='Base votos'!H201/'Base votos'!R201 -> 0.17699279 | H14: ='Base votos'!H234/'Base votos'!R234 -> 0.16932482 | I14: =(C14-B14)*100 -> -1.6814083 | J14: =(E14-D14)*100 -> 0.2241995 | K14: =(F14-E14)*100 -> -1.2739129 | L14: =(F14-D14)*100 -> -1.0497134 | M14: =(H14-G14)*100 -> -0.76679706
A15: PRI | B15: ='Base votos'!I36/'Base votos'!R36 -> 0.13716828 | C15: ='Base votos'!I69/'Base votos'!R69 -> 0.095337012 | D15: ='Base votos'!I102/'Base votos'!R102 -> 0.16606904 | E15: ='Base votos'!I135/'Base votos'!R135 -> 0.17769976 | F15: ='Base votos'!I168/'Base votos'!R168 -> 0.11136567 | G15: ='Base votos'!I201/'Base votos'!R201 -> 0.15972022 | H15: ='Base votos'!I234/'Base votos'!R234 -> 0.10883451 | I15: =(C15-B15)*100 -> -4.1831265 | J15: =(E15-D15)*100 -> 1.1630724 | K15: =(F15-E15)*100 -> -6.6334096 | L15: =(F15-D15)*100 -> -5.4703371 | M15: =(H15-G15)*100 -> -5.0885716
A16: PRD | B16: ='Base votos'!J36/'Base votos'!R36 -> 0.027473005 | C16: ='Base votos'!J69/'Base votos'!R69 -> 0.017564181 | D16: ='Base votos'!J102/'Base votos'!R102 -> 0.052276183 | E16: ='Base votos'!J135/'Base votos'!R135 -> 0.035900582 | F16: ='Base votos'!J168/'Base votos'!R168 -> 0.023446844 | G16: ='Base votos'!J201/'Base votos'!R201 -> 0.052228795 | H16: ='Base votos'!J234/'Base votos'!R234 -> 0.021836277 | I16: =(C16-B16)*100 -> -0.99088231 | J16: =(E16-D16)*100 -> -1.6375601 | K16: =(F16-E16)*100 -> -1.2453738 | L16: =(F16-D16)*100 -> -2.8829339 | M16: =(H16-G16)*100 -> -3.0392518
A17: MC | B17: ='Base votos'!K36/'Base votos'!R36 -> 0.0168464 | C17: ='Base votos'!K69/'Base votos'!R69 -> 0.10321369 | D17: ='Base votos'!K102/'Base votos'!R102 -> 0.043475422 | E17: ='Base votos'!K135/'Base votos'!R135 -> 0.070191035 | F17: ='Base votos'!K168/'Base votos'!R168 -> 0.10926164 | G17: ='Base votos'!K201/'Base votos'!R201 -> 0.046146247 | H17: ='Base votos'!K234/'Base votos'!R234 -> 0.10879721 | I17: =(C17-B17)*100 -> 8.6367291 | J17: =(E17-D17)*100 -> 2.6715612 | K17: =(F17-E17)*100 -> 3.9070609 | L17: =(F17-D17)*100 -> 6.5786221 | M17: =(H17-G17)*100 -> 6.2650963
A18: Nueva Alianza | B18: ='Base votos'!L36/'Base votos'!R36 -> 0.0092256761 | C18: ='Base votos'!L69/'Base votos'!R69 -> 0 | D18: ='Base votos'!L102/'Base votos'!R102 -> 0.024388294 | E18: ='Base votos'!L135/'Base votos'!R135 -> 0 | F18: ='Base votos'!L168/'Base votos'!R168 -> 0 | G18: ='Base votos'!L201/'Base votos'!R201 -> 0.022732766 | H18: ='Base votos'!L234/'Base votos'!R234 -> 0 | I18: =(C18-B18)*100 -> -0.92256761 | J18: =(E18-D18)*100 -> -2.4388294 | K18: =(F18-E18)*100 -> 0 | L18: =(F18-D18)*100 -> -2.4388294 | M18: =(H18-G18)*100 -> -2.2732766
A19: RSP | B19: ='Base votos'!M36/'Base votos'!R36 -> 0 | C19: ='Base votos'!M69/'Base votos'!R69 -> 0 | D19: ='Base votos'!M102/'Base votos'!R102 -> 0 | E19: ='Base votos'!M135/'Base votos'!R135 -> 0.017670227 | F19: ='Base votos'!M168/'Base votos'!R168 -> 0 | G19: ='Base votos'!M201/'Base votos'!R201 -> 0 | H19: ='Base votos'!M234/'Base votos'!R234 -> 0 | I19: =(C19-B19)*100 -> 0 | J19: =(E19-D19)*100 -> 1.7670227 | K19: =(F19-E19)*100 -> -1.7670227 | L19: =(F19-D19)*100 -> 0 | M19: =(H19-G19)*100 -> 0
A20: FXM | B20: ='Base votos'!N36/'Base votos'!R36 -> 0 | C20: ='Base votos'!N69/'Base votos'!R69 -> 0 | D20: ='Base votos'!N102/'Base votos'!R102 -> 0 | E20: ='Base votos'!N135/'Base votos'!R135 -> 0.02476198 | F20: ='Base votos'!N168/'Base votos'!R168 -> 0 | G20: ='Base votos'!N201/'Base votos'!R201 -> 0 | H20: ='Base votos'!N234/'Base votos'!R234 -> 0 | I20: =(C20-B20)*100 -> 0 | J20: =(E20-D20)*100 -> 2.476198 | K20: =(F20-E20)*100 -> -2.476198 | L20: =(F20-D20)*100 -> 0 | M20: =(H20-G20)*100 -> 0
A21: Independientes | B21: ='Base votos'!O36/'Base votos'!R36 -> 0.052895613 | C21: ='Base votos'!O69/'Base votos'!R69 -> 0 | D21: ='Base votos'!O102/'Base votos'!R102 -> 0.0095798336 | E21: ='Base votos'!O135/'Base votos'!R135 -> 0.00090152208 | F21: ='Base votos'!O168/'Base votos'!R168 -> 0.0012109682 | G21: ='Base votos'!O201/'Base votos'!R201 -> 0.019564516 | H21: ='Base votos'!O234/'Base votos'!R234 -> 0 | I21: =(C21-B21)*100 -> -5.2895613 | J21: =(E21-D21)*100 -> -0.86783116 | K21: =(F21-E21)*100 -> 0.03094461 | L21: =(F21-D21)*100 -> -0.83688655 | M21: =(H21-G21)*100 -> -1.9564516
A22: No registrados | B22: ='Base votos'!P36/'Base votos'!R36 -> 0.00056494294 | C22: ='Base votos'!P69/'Base votos'!R69 -> 0.0013825792 | D22: ='Base votos'!P102/'Base votos'!R102 -> 0.00058541484 | E22: ='Base votos'!P135/'Base votos'!R135 -> 0.00085314087 | F22: ='Base votos'!P168/'Base votos'!R168 -> 0.00082952631 | G22: ='Base votos'!P201/'Base votos'!R201 -> 0.00056127978 | H22: ='Base votos'!P234/'Base votos'!R234 -> 0.00078481793 | I22: =(C22-B22)*100 -> 0.081763621 | J22: =(E22-D22)*100 -> 0.026772603 | K22: =(F22-E22)*100 -> -0.0023614558 | L22: =(F22-D22)*100 -> 0.024411148 | M22: =(H22-G22)*100 -> 0.022353815
A23: Morena + PT | B23: =('Base votos'!D36+'Base votos'!E36)/'Base votos'!R36 -> 0.50656769 | C23: =('Base votos'!D69+'Base votos'!E69)/'Base votos'!R69 -> 0.52112208 | D23: =('Base votos'!D102+'Base votos'!E102)/'Base votos'!R102 -> 0.41304512 | E23: =('Base votos'!D135+'Base votos'!E135)/'Base votos'!R135 -> 0.37372191 | F23: =('Base votos'!D168+'Base votos'!E168)/'Base votos'!R168 -> 0.46409013 | G23: =('Base votos'!D201+'Base votos'!E201)/'Base votos'!R201 -> 0.41445247 | H23: =('Base votos'!D234+'Base votos'!E234)/'Base votos'!R234 -> 0.4624483 | I23: =(C23-B23)*100 -> 1.4554398 | J23: =(E23-D23)*100 -> -3.9323209 | K23: =(F23-E23)*100 -> 9.0368226 | L23: =(F23-D23)*100 -> 5.1045017 | M23: =(H23-G23)*100 -> 4.7995831
A24: PAN + PRI + PRD | B24: =('Base votos'!H36+'Base votos'!I36+'Base votos'!J36)/'Base votos'!R36 -> 0.34307212 | C24: =('Base votos'!H69+'Base votos'!I69+'Base votos'!J69)/'Base votos'!R69 -> 0.27451795 | D24: =('Base votos'!H102+'Base votos'!I102+'Base votos'!J102)/'Base votos'!R102 -> 0.39878699 | E24: =('Base votos'!H135+'Base votos'!I135+'Base votos'!J135)/'Base votos'!R135 -> 0.39628411 | F24: =('Base votos'!H168+'Base votos'!I168+'Base votos'!J168)/'Base votos'!R168 -> 0.30475714 | G24: =('Base votos'!H201+'Base votos'!I201+'Base votos'!J201)/'Base votos'!R201 -> 0.38894181 | H24: =('Base votos'!H234+'Base votos'!I234+'Base votos'!J234)/'Base votos'!R234 -> 0.2999956 | I24: =(C24-B24)*100 -> -6.855417 | J24: =(E24-D24)*100 -> -0.25028814 | K24: =(F24-E24)*100 -> -9.1526963 | L24: =(F24-D24)*100 -> -9.4029845 | M24: =(H24-G24)*100 -> -8.8946204
A25: Bloque de Morena y aliados (como compitió) | B25: ='Base votos'!U36/'Base votos'!R36 -> 0.5319367 | C25: ='Base votos'!U69/'Base votos'!R69 -> 0.59759476 | D25: ='Base votos'!U102/'Base votos'!R102 -> 0.43584652 | E25: ='Base votos'!U135/'Base votos'!R135 -> 0.42777573 | F25: ='Base votos'!U168/'Base votos'!R168 -> 0.54711544 | G25: ='Base votos'!U201/'Base votos'!R201 -> 0.43651018 | H25: ='Base votos'!U234/'Base votos'!R234 -> 0.55092595 | I25: =(C25-B25)*100 -> 6.5658059 | J25: =(E25-D25)*100 -> -0.80707906 | K25: =(F25-E25)*100 -> 11.933971 | L25: =(F25-D25)*100 -> 11.126892 | M25: =(H25-G25)*100 -> 11.441577
A26: Bloque del PAN y aliados (como compitió) | B26: ='Base votos'!V36/'Base votos'!R36 -> 0.22275024 | C26: ='Base votos'!V69/'Base votos'!R69 -> 0.27451795 | D26: ='Base votos'!V102/'Base votos'!R102 -> 0.27619337 | E26: ='Base votos'!V135/'Base votos'!R135 -> 0.39628411 | F26: ='Base votos'!V168/'Base votos'!R168 -> 0.30475714 | G26: ='Base votos'!V201/'Base votos'!R201 -> 0.27536783 | H26: ='Base votos'!V234/'Base votos'!R234 -> 0.2999956 | I26: =(C26-B26)*100 -> 5.1767706 | J26: =(E26-D26)*100 -> 12.009074 | K26: =(F26-E26)*100 -> -9.1526963 | L26: =(F26-D26)*100 -> 2.8563774 | M26: =(H26-G26)*100 -> 2.4627773
A27: Tercer bloque (PRI en 2018 / MC en 2021-24) | B27: ='Base votos'!W36/'Base votos'!R36 -> 0.16409971 | C27: ='Base votos'!W69/'Base votos'!R69 -> 0.10321369 | D27: ='Base votos'!W102/'Base votos'!R102 -> 0.23796173 | E27: ='Base votos'!W135/'Base votos'!R135 -> 0.070191035 | F27: ='Base votos'!W168/'Base votos'!R168 -> 0.10926164 | G27: ='Base votos'!W201/'Base votos'!R201 -> 0.22664358 | H27: ='Base votos'!W234/'Base votos'!R234 -> 0.10879721 | I27: =(C27-B27)*100 -> -6.0886017 | J27: =(E27-D27)*100 -> -16.777069 | K27: =(F27-E27)*100 -> 3.9070609 | L27: =(F27-D27)*100 -> -12.870008 | M27: =(H27-G27)*100 -> -11.784637
A28: Bloque ganador (nacional) | B28: Morena y aliados | C28: Morena y aliados | D28: Morena y aliados | E28: Morena y aliados | F28: Morena y aliados | G28: Morena y aliados | H28: Morena y aliados
A29: Estados ganados por Morena y aliados (de 32) | B29: 31 | C29: 31 | D29: 25 | E29: 20 | F29: 28 | G29: 25 | H29: 29
A30: Estados ganados por el bloque del PAN | B30: 1 | C30: 1 | D30: 6 | E30: 11 | F30: 4 | G30: 6 | H30: 3
A31: Estados ganados por el tercer bloque | B31: 0 | C31: 0 | D31: 1 | E31: 1 | F31: 0 | G31: 1 | H31: 0

Sheet Presidencia - Partidos
A1: Presidencia: voto por partido y cambio por estado (2018 – 2024)
A2: % sobre el total de votos emitidos. El voto de coalición se reparte entre sus partidos (ver Metodología). Las columnas Δ están en puntos porcentuales: verde = sube, rojo = baja.
B3: Morena | E3: PT | H3: PVEM | K3: PAN | N3: PRI | Q3: PRD | T3: MC | W3: Morena + PT | Z3: PAN + PRI + PRD
A4: Estado | B4: 2018 | C4: 2024 | D4: Δ 2024 vs 2018 (pts) | E4: 2018 | F4: 2024 | G4: Δ 2024 vs 2018 (pts) | H4: 2018 | I4: 2024 | J4: Δ 2024 vs 2018 (pts) | K4: 2018 | L4: 2024 | M4: Δ 2024 vs 2018 (pts) | N4: 2018 | O4: 2024 | P4: Δ 2024 vs 2018 (pts) | Q4: 2018 | R4: 2024 | S4: Δ 2024 vs 2018 (pts) | T4: 2018 | U4: 2024 | V4: Δ 2024 vs 2018 (pts) | W4: 2018 | X4: 2024 | Y4: Δ 2024 vs 2018 (pts) | Z4: 2018 | AA4: 2024 | AB4: Δ 2024 vs 2018 (pts)
A5: Aguascalientes | B5: =('Base votos'!D4)/'Base votos'!R4 -> 0.32775447 | C5: =('Base votos'!D37)/'Base votos'!R37 -> 0.35528982 | D5: =(C5-B5)*100 -> 2.7535349 | E5: =('Base votos'!E4)/'Base votos'!R4 -> 0.04720142 | F5: =('Base votos'!E37)/'Base votos'!R37 -> 0.036545279 | G5: =(F5-E5)*100 -> -1.0656141 | H5: =('Base votos'!F4)/'Base votos'!R4 -> 0.011707235 | I5: =('Base votos'!F37)/'Base votos'!R37 -> 0.035496111 | J5: =(I5-H5)*100 -> 2.3788876 | K5: =('Base votos'!H4)/'Base votos'!R4 -> 0.2950619 | L5: =('Base votos'!H37)/'Base votos'!R37 -> 0.36916316 | M5: =(L5-K5)*100 -> 7.4101261 | N5: =('Base votos'!I4)/'Base votos'!R4 -> 0.16166999 | O5: =('Base votos'!I37)/'Base votos'!R37 -> 0.06808487 | P5: =(O5-N5)*100 -> -9.3585117 | Q5: =('Base votos'!J4)/'Base votos'!R4 -> 0.014827858 | R5: =('Base votos'!J37)/'Base votos'!R37 -> 0.022437793 | S5: =(R5-Q5)*100 -> 0.7609935 | T5: =('Base votos'!K4)/'Base votos'!R4 -> 0.0091016671 | U5: =('Base votos'!K37)/'Base votos'!R37 -> 0.089303887 | V5: =(U5-T5)*100 -> 8.020222 | W5: =('Base votos'!D4+'Base votos'!E4)/'Base votos'!R4 -> 0.37495589 | X5: =('Base votos'!D37+'Base votos'!E37)/'Base votos'!R37 -> 0.3918351 | Y5: =(X5-W5)*100 -> 1.6879208 | Z5: =('Base votos'!H4+'Base votos'!I4+'Base votos'!J4)/'Base votos'!R4 -> 0.47155974 | AA5: =('Base votos'!H37+'Base votos'!I37+'Base votos'!J37)/'Base votos'!R37 -> 0.45968582 | AB5: =(AA5-Z5)*100 -> -1.1873921
A6: Baja California | B6: =('Base votos'!D5)/'Base votos'!R5 -> 0.5503232 | C6: =('Base votos'!D38)/'Base votos'!R38 -> 0.54523361 | D6: =(C6-B6)*100 -> -0.50895878 | E6: =('Base votos'!E5)/'Base votos'!R5 -> 0.060106839 | F6: =('Base votos'!E38)/'Base votos'!R38 -> 0.061074783 | G6: =(F6-E6)*100 -> 0.09679441 | H6: =('Base votos'!F5)/'Base votos'!R5 -> 0.0068929702 | I6: =('Base votos'!F38)/'Base votos'!R38 -> 0.060198688 | J6: =(I6-H6)*100 -> 5.3305718 | K6: =('Base votos'!H5)/'Base votos'!R5 -> 0.17170552 | L6: =('Base votos'!H38)/'Base votos'!R38 -> 0.15305771 | M6: =(L6-K6)*100 -> -1.8647809 | N6: =('Base votos'!I5)/'Base votos'!R5 -> 0.074396804 | O6: =('Base votos'!I38)/'Base votos'!R38 -> 0.047957712 | P6: =(O6-N6)*100 -> -2.6439093 | Q6: =('Base votos'!J5)/'Base votos'!R5 -> 0.010282101 | R6: =('Base votos'!J38)/'Base votos'!R38 -> 0.010898956 | S6: =(R6-Q6)*100 -> 0.061685474 | T6: =('Base votos'!K5)/'Base votos'!R5 -> 0.0095437917 | U6: =('Base votos'!K38)/'Base votos'!R38 -> 0.099505682 | V6: =(U6-T6)*100 -> 8.9961891 | W6: =('Base votos'!D5+'Base votos'!E5)/'Base votos'!R5 -> 0.61043004 | X6: =('Base votos'!D38+'Base votos'!E38)/'Base votos'!R38 -> 0.6063084 | Y6: =(X6-W6)*100 -> -0.41216437 | Z6: =('Base votos'!H5+'Base votos'!I5+'Base votos'!J5)/'Base votos'!R5 -> 0.25638443 | AA6: =('Base votos'!H38+'Base votos'!I38+'Base votos'!J38)/'Base votos'!R38 -> 0.21191438 | AB6: =(AA6-Z6)*100 -> -4.4470047
A7: Baja California Sur | B7: =('Base votos'!D6)/'Base votos'!R6 -> 0.51855141 | C7: =('Base votos'!D39)/'Base votos'!R39 -> 0.44368092 | D7: =(C7-B7)*100 -> -7.4870493 | E7: =('Base votos'!E6)/'Base votos'!R6 -> 0.090815747 | F7: =('Base votos'!E39)/'Base votos'!R39 -> 0.087606479 | G7: =(F7-E7)*100 -> -0.32092676 | H7: =('Base votos'!F6)/'Base votos'!R6 -> 0.0099673807 | I7: =('Base votos'!F39)/'Base votos'!R39 -> 0.060104855 | J7: =(I7-H7)*100 -> 5.0137474 | K7: =('Base votos'!H6)/'Base votos'!R6 -> 0.17599245 | L7: =('Base votos'!H39)/'Base votos'!R39 -> 0.24096045 | M7: =(L7-K7)*100 -> 6.4968008 | N7: =('Base votos'!I6)/'Base votos'!R6 -> 0.074568818 | O7: =('Base votos'!I39)/'Base votos'!R39 -> 0.043094602 | P7: =(O7-N7)*100 -> -3.1474216 | Q7: =('Base votos'!J6)/'Base votos'!R6 -> 0.0058041256 | R7: =('Base votos'!J39)/'Base votos'!R39 -> 0.013325924 | S7: =(R7-Q7)*100 -> 0.75217979 | T7: =('Base votos'!K6)/'Base votos'!R6 -> 0.0057116822 | U7: =('Base votos'!K39)/'Base votos'!R39 -> 0.087697632 | V7: =(U7-T7)*100 -> 8.198595 | W7: =('Base votos'!D6+'Base votos'!E6)/'Base votos'!R6 -> 0.60936716 | X7: =('Base votos'!D39+'Base votos'!E39)/'Base votos'!R39 -> 0.5312874 | Y7: =(X7-W7)*100 -> -7.8079761 | Z7: =('Base votos'!H6+'Base votos'!I6+'Base votos'!J6)/'Base votos'!R6 -> 0.25636539 | AA7: =('Base votos'!H39+'Base votos'!I39+'Base votos'!J39)/'Base votos'!R39 -> 0.29738098 | AB7: =(AA7-Z7)*100 -> 4.101559
A8: Campeche | B8: =('Base votos'!D7)/'Base votos'!R7 -> 0.50673678 | C8: =('Base votos'!D40)/'Base votos'!R40 -> 0.50204278 | D8: =(C8-B8)*100 -> -0.46940024 | E8: =('Base votos'!E7)/'Base votos'!R7 -> 0.07617446 | F8: =('Base votos'!E40)/'Base votos'!R40 -> 0.061871164 | G8: =(F8-E8)*100 -> -1.4303297 | H8: =('Base votos'!F7)/'Base votos'!R7 -> 0.011511588 | I8: =('Base votos'!F40)/'Base votos'!R40 -> 0.049064552 | J8: =(I8-H8)*100 -> 3.7552963 | K8: =('Base votos'!H7)/'Base votos'!R7 -> 0.10099278 | L8: =('Base votos'!H40)/'Base votos'!R40 -> 0.056541013 | M8: =(L8-K8)*100 -> -4.4451765 | N8: =('Base votos'!I7)/'Base votos'!R7 -> 0.19231582 | O8: =('Base votos'!I40)/'Base votos'!R40 -> 0.091808177 | P8: =(O8-N8)*100 -> -10.050764 | Q8: =('Base votos'!J7)/'Base votos'!R7 -> 0.011702892 | R8: =('Base votos'!J40)/'Base votos'!R40 -> 0.0064923643 | S8: =(R8-Q8)*100 -> -0.52105277 | T8: =('Base votos'!K7)/'Base votos'!R7 -> 0.008352853 | U8: =('Base votos'!K40)/'Base votos'!R40 -> 0.20991087 | V8: =(U8-T8)*100 -> 20.155802 | W8: =('Base votos'!D7+'Base votos'!E7)/'Base votos'!R7 -> 0.58291124 | X8: =('Base votos'!D40+'Base votos'!E40)/'Base votos'!R40 -> 0.56391394 | Y8: =(X8-W8)*100 -> -1.8997299 | Z8: =('Base votos'!H7+'Base votos'!I7+'Base votos'!J7)/'Base votos'!R7 -> 0.30501149 | AA8: =('Base votos'!H40+'Base votos'!I40+'Base votos'!J40)/'Base votos'!R40 -> 0.15484155 | AB8: =(AA8-Z8)*100 -> -15.016994
A9: Coahuila | B9: =('Base votos'!D8)/'Base votos'!R8 -> 0.37643168 | C9: =('Base votos'!D41)/'Base votos'!R41 -> 0.43766354 | D9: =(C9-B9)*100 -> 6.1231858 | E9: =('Base votos'!E8)/'Base votos'!R8 -> 0.049474565 | F9: =('Base votos'!E41)/'Base votos'!R41 -> 0.050048813 | G9: =(F9-E9)*100 -> 0.057424812 | H9: =('Base votos'!F8)/'Base votos'!R8 -> 0.0091302332 | I9: =('Base votos'!F41)/'Base votos'!R41 -> 0.049476651 | J9: =(I9-H9)*100 -> 4.0346417 | K9: =('Base votos'!H8)/'Base votos'!R8 -> 0.20717793 | L9: =('Base votos'!H41)/'Base votos'!R41 -> 0.063165753 | M9: =(L9-K9)*100 -> -14.401218 | N9: =('Base votos'!I8)/'Base votos'!R8 -> 0.24566414 | O9: =('Base votos'!I41)/'Base votos'!R41 -> 0.31029912 | P9: =(O9-N9)*100 -> 6.4634976 | Q9: =('Base votos'!J8)/'Base votos'!R8 -> 0.0085434198 | R9: =('Base votos'!J41)/'Base votos'!R41 -> 0.015031702 | S9: =(R9-Q9)*100 -> 0.6488282 | T9: =('Base votos'!K8)/'Base votos'!R8 -> 0.0084996822 | U9: =('Base votos'!K41)/'Base votos'!R41 -> 0.054041993 | V9: =(U9-T9)*100 -> 4.554231 | W9: =('Base votos'!D8+'Base votos'!E8)/'Base votos'!R8 -> 0.42590624 | X9: =('Base votos'!D41+'Base votos'!E41)/'Base votos'!R41 -> 0.48771235 | Y9: =(X9-W9)*100 -> 6.1806106 | Z9: =('Base votos'!H8+'Base votos'!I8+'Base votos'!J8)/'Base votos'!R8 -> 0.46138549 | AA9: =('Base votos'!H41+'Base votos'!I41+'Base votos'!J41)/'Base votos'!R41 -> 0.38849657 | AB9: =(AA9-Z9)*100 -> -7.288892
A10: Colima | B10: =('Base votos'!D9)/'Base votos'!R9 -> 0.48294827 | C10: =('Base votos'!D42)/'Base votos'!R42 -> 0.42988343 | D10: =(C10-B10)*100 -> -5.3064837 | E10: =('Base votos'!E9)/'Base votos'!R9 -> 0.070209229 | F10: =('Base votos'!E42)/'Base votos'!R42 -> 0.047192734 | G10: =(F10-E10)*100 -> -2.3016496 | H10: =('Base votos'!F9)/'Base votos'!R9 -> 0.022344764 | I10: =('Base votos'!F42)/'Base votos'!R42 -> 0.067001244 | J10: =(I10-H10)*100 -> 4.465648 | K10: =('Base votos'!H9)/'Base votos'!R9 -> 0.14258492 | L10: =('Base votos'!H42)/'Base votos'!R42 -> 0.14773654 | M10: =(L10-K10)*100 -> 0.51516207 | N10: =('Base votos'!I9)/'Base votos'!R9 -> 0.15048562 | O10: =('Base votos'!I42)/'Base votos'!R42 -> 0.13676492 | P10: =(O10-N10)*100 -> -1.3720703 | Q10: =('Base votos'!J9)/'Base votos'!R9 -> 0.0085749716 | R10: =('Base votos'!J42)/'Base votos'!R42 -> 0.015113824 | S10: =(R10-Q10)*100 -> 0.65388521 | T10: =('Base votos'!K9)/'Base votos'!R9 -> 0.014265235 | U10: =('Base votos'!K42)/'Base votos'!R42 -> 0.13332562 | V10: =(U10-T10)*100 -> 11.906038 | W10: =('Base votos'!D9+'Base votos'!E9)/'Base votos'!R9 -> 0.5531575 | X10: =('Base votos'!D42+'Base votos'!E42)/'Base votos'!R42 -> 0.47707616 | Y10: =(X10-W10)*100 -> -7.6081333 | Z10: =('Base votos'!H9+'Base votos'!I9+'Base votos'!J9)/'Base votos'!R9 -> 0.30164552 | AA10: =('Base votos'!H42+'Base votos'!I42+'Base votos'!J42)/'Base votos'!R42 -> 0.29961528 | AB10: =(AA10-Z10)*100 -> -0.20302306
A11: Chiapas | B11: =('Base votos'!D10)/'Base votos'!R10 -> 0.49750294 | C11: =('Base votos'!D43)/'Base votos'!R43 -> 0.42280298 | D11: =(C11-B11)*100 -> -7.4699962 | E11: =('Base votos'!E10)/'Base votos'!R10 -> 0.078698905 | F11: =('Base votos'!E43)/'Base votos'!R43 -> 0.10936983 | G11: =(F11-E11)*100 -> 3.0670926 | H11: =('Base votos'!F10)/'Base votos'!R10 -> 0.10271927 | I11: =('Base votos'!F43)/'Base votos'!R43 -> 0.1833444 | J11: =(I11-H11)*100 -> 8.0625129 | K11: =('Base votos'!H10)/'Base votos'!R10 -> 0.043178529 | L11: =('Base votos'!H43)/'Base votos'!R43 -> 0.059546503 | M11: =(L11-K11)*100 -> 1.6367973 | N11: =('Base votos'!I10)/'Base votos'!R10 -> 0.1128246 | O11: =('Base votos'!I43)/'Base votos'!R43 -> 0.092570517 | P11: =(O11-N11)*100 -> -2.0254087 | Q11: =('Base votos'!J10)/'Base votos'!R10 -> 0.02329355 | R11: =('Base votos'!J43)/'Base votos'!R43 -> 0.014827183 | S11: =(R11-Q11)*100 -> -0.84663675 | T11: =('Base votos'!K10)/'Base votos'!R10 -> 0.01520376 | U11: =('Base votos'!K43)/'Base votos'!R43 -> 0.07404129 | V11: =(U11-T11)*100 -> 5.883753 | W11: =('Base votos'!D10+'Base votos'!E10)/'Base votos'!R10 -> 0.57620184 | X11: =('Base votos'!D43+'Base votos'!E43)/'Base votos'!R43 -> 0.53217281 | Y11: =(X11-W11)*100 -> -4.4029036 | Z11: =('Base votos'!H10+'Base votos'!I10+'Base votos'!J10)/'Base votos'!R10 -> 0.17929668 | AA11: =('Base votos'!H43+'Base votos'!I43+'Base votos'!J43)/'Base votos'!R43 -> 0.1669442 | AB11: =(AA11-Z11)*100 -> -1.2352481
A12: Chihuahua | B12: =('Base votos'!D11)/'Base votos'!R11 -> 0.34606628 | C12: =('Base votos'!D44)/'Base votos'!R44 -> 0.43727461 | D12: =(C12-B12)*100 -> 9.120833 | E12: =('Base votos'!E11)/'Base votos'!R11 -> 0.057258121 | F12: =('Base votos'!E44)/'Base votos'!R44 -> 0.052445713 | G12: =(F12-E12)*100 -> -0.48124077 | H12: =('Base votos'!F11)/'Base votos'!R11 -> 0.012025115 | I12: =('Base votos'!F44)/'Base votos'!R44 -> 0.048915486 | J12: =(I12-H12)*100 -> 3.689037 | K12: =('Base votos'!H11)/'Base votos'!R11 -> 0.25960574 | L12: =('Base votos'!H44)/'Base votos'!R44 -> 0.23644258 | M12: =(L12-K12)*100 -> -2.3163161 | N12: =('Base votos'!I11)/'Base votos'!R11 -> 0.13877588 | O12: =('Base votos'!I44)/'Base votos'!R44 -> 0.089129439 | P12: =(O12-N12)*100 -> -4.9646439 | Q12: =('Base votos'!J11)/'Base votos'!R11 -> 0.011865887 | R12: =('Base votos'!J44)/'Base votos'!R44 -> 0.014736847 | S12: =(R12-Q12)*100 -> 0.28709606 | T12: =('Base votos'!K11)/'Base votos'!R11 -> 0.013480252 | U12: =('Base votos'!K44)/'Base votos'!R44 -> 0.095507685 | V12: =(U12-T12)*100 -> 8.2027433 | W12: =('Base votos'!D11+'Base votos'!E11)/'Base votos'!R11 -> 0.4033244 | X12: =('Base votos'!D44+'Base votos'!E44)/'Base votos'!R44 -> 0.48972032 | Y12: =(X12-W12)*100 -> 8.6395922 | Z12: =('Base votos'!H11+'Base votos'!I11+'Base votos'!J11)/'Base votos'!R11 -> 0.41024751 | AA12: =('Base votos'!H44+'Base votos'!I44+'Base votos'!J44)/'Base votos'!R44 -> 0.34030887 | AB12: =(AA12-Z12)*100 -> -6.9938639
A13: Ciudad de México | B13: =('Base votos'!D12)/'Base votos'!R12 -> 0.50174792 | C13: =('Base votos'!D45)/'Base votos'!R45 -> 0.44764016 | D13: =(C13-B13)*100 -> -5.410776 | E13: =('Base votos'!E12)/'Base votos'!R12 -> 0.048153784 | F13: =('Base votos'!E45)/'Base votos'!R45 -> 0.051248219 | G13: =(F13-E13)*100 -> 0.30944347 | H13: =('Base votos'!F12)/'Base votos'!R12 -> 0.0071204106 | I13: =('Base votos'!F45)/'Base votos'!R45 -> 0.053119624 | J13: =(I13-H13)*100 -> 4.5999213 | K13: =('Base votos'!H12)/'Base votos'!R12 -> 0.17878331 | L13: =('Base votos'!H45)/'Base votos'!R45 -> 0.24811009 | M13: =(L13-K13)*100 -> 6.9326778 | N13: =('Base votos'!I12)/'Base votos'!R12 -> 0.10870983 | O13: =('Base votos'!I45)/'Base votos'!R45 -> 0.074310515 | P13: =(O13-N13)*100 -> -3.4399317 | Q13: =('Base votos'!J12)/'Base votos'!R12 -> 0.050703606 | R13: =('Base votos'!J45)/'Base votos'!R45 -> 0.023033585 | S13: =(R13-Q13)*100 -> -2.7670021 | T13: =('Base votos'!K12)/'Base votos'!R12 -> 0.009627871 | U13: =('Base votos'!K45)/'Base votos'!R45 -> 0.08345176 | V13: =(U13-T13)*100 -> 7.3823889 | W13: =('Base votos'!D12+'Base votos'!E12)/'Base votos'!R12 -> 0.5499017 | X13: =('Base votos'!D45+'Base votos'!E45)/'Base votos'!R45 -> 0.49888837 | Y13: =(X13-W13)*100 -> -5.1013326 | Z13: =('Base votos'!H12+'Base votos'!I12+'Base votos'!J12)/'Base votos'!R12 -> 0.33819675 | AA13: =('Base votos'!H45+'Base votos'!I45+'Base votos'!J45)/'Base votos'!R45 -> 0.34545419 | AB13: =(AA13-Z13)*100 -> 0.72574399
A14: Durango | B14: =('Base votos'!D13)/'Base votos'!R13 -> 0.34482599 | C14: =('Base votos'!D46)/'Base votos'!R46 -> 0.46272355 | D14: =(C14-B14)*100 -> 11.789756 | E14: =('Base votos'!E13)/'Base votos'!R13 -> 0.092850766 | F14: =('Base votos'!E46)/'Base votos'!R46 -> 0.068570181 | G14: =(F14-E14)*100 -> -2.4280585 | H14: =('Base votos'!F13)/'Base votos'!R13 -> 0.013614278 | I14: =('Base votos'!F46)/'Base votos'!R46 -> 0.053160185 | J14: =(I14-H14)*100 -> 3.9545907 | K14: =('Base votos'!H13)/'Base votos'!R13 -> 0.23157084 | L14: =('Base votos'!H46)/'Base votos'!R46 -> 0.12647546 | M14: =(L14-K14)*100 -> -10.509538 | N14: =('Base votos'!I13)/'Base votos'!R13 -> 0.1724607 | O14: =('Base votos'!I46)/'Base votos'!R46 -> 0.1780976 | P14: =(O14-N14)*100 -> 0.56369013 | Q14: =('Base votos'!J13)/'Base votos'!R13 -> 0.011843836 | R14: =('Base votos'!J46)/'Base votos'!R46 -> 0.016751614 | S14: =(R14-Q14)*100 -> 0.49077786 | T14: =('Base votos'!K13)/'Base votos'!R13 -> 0.012743368 | U14: =('Base votos'!K46)/'Base votos'!R46 -> 0.072060957 | V14: =(U14-T14)*100 -> 5.9317589 | W14: =('Base votos'!D13+'Base votos'!E13)/'Base votos'!R13 -> 0.43767675 | X14: =('Base votos'!D46+'Base votos'!E46)/'Base votos'!R46 -> 0.53129373 | Y14: =(X14-W14)*100 -> 9.3616976 | Z14: =('Base votos'!H13+'Base votos'!I13+'Base votos'!J13)/'Base votos'!R13 -> 0.41587537 | AA14: =('Base votos'!H46+'Base votos'!I46+'Base votos'!J46)/'Base votos'!R46 -> 0.32132467 | AB14: =(AA14-Z14)*100 -> -9.4550702
A15: Guanajuato | B15: =('Base votos'!D14)/'Base votos'!R14 -> 0.25005086 | C15: =('Base votos'!D47)/'Base votos'!R47 -> 0.38875036 | D15: =(C15-B15)*100 -> 13.86995 | E15: =('Base votos'!E14)/'Base votos'!R14 -> 0.039533644 | F15: =('Base votos'!E47)/'Base votos'!R47 -> 0.035536691 | G15: =(F15-E15)*100 -> -0.39969534 | H15: =('Base votos'!F14)/'Base votos'!R14 -> 0.026151749 | I15: =('Base votos'!F47)/'Base votos'!R47 -> 0.04786321 | J15: =(I15-H15)*100 -> 2.1711461 | K15: =('Base votos'!H14)/'Base votos'!R14 -> 0.37002598 | L15: =('Base votos'!H47)/'Base votos'!R47 -> 0.33280587 | M15: =(L15-K15)*100 -> -3.7220118 | N15: =('Base votos'!I14)/'Base votos'!R14 -> 0.12729553 | O15: =('Base votos'!I47)/'Base votos'!R47 -> 0.056043075 | P15: =(O15-N15)*100 -> -7.1252456 | Q15: =('Base votos'!J14)/'Base votos'!R14 -> 0.019795639 | R15: =('Base votos'!J47)/'Base votos'!R47 -> 0.011038414 | S15: =(R15-Q15)*100 -> -0.87572252 | T15: =('Base votos'!K14)/'Base votos'!R14 -> 0.01453544 | U15: =('Base votos'!K47)/'Base votos'!R47 -> 0.10560684 | V15: =(U15-T15)*100 -> 9.1071404 | W15: =('Base votos'!D14+'Base votos'!E14)/'Base votos'!R14 -> 0.2895845 | X15: =('Base votos'!D47+'Base votos'!E47)/'Base votos'!R47 -> 0.42428705 | Y15: =(X15-W15)*100 -> 13.470254 | Z15: =('Base votos'!H14+'Base votos'!I14+'Base votos'!J14)/'Base votos'!R14 -> 0.51711715 | AA15: =('Base votos'!H47+'Base votos'!I47+'Base votos'!J47)/'Base votos'!R47 -> 0.39988735 | AB15: =(AA15-Z15)*100 -> -11.72298
A16: Guerrero | B16: =('Base votos'!D15)/'Base votos'!R15 -> 0.51704752 | C16: =('Base votos'!D48)/'Base votos'!R48 -> 0.52832333 | D16: =(C16-B16)*100 -> 1.1275815 | E16: =('Base votos'!E15)/'Base votos'!R15 -> 0.084574289 | F16: =('Base votos'!E48)/'Base votos'!R48 -> 0.086797626 | G16: =(F16-E16)*100 -> 0.22233366 | H16: =('Base votos'!F15)/'Base votos'!R15 -> 0.026184369 | I16: =('Base votos'!F48)/'Base votos'!R48 -> 0.10150635 | J16: =(I16-H16)*100 -> 7.5321986 | K16: =('Base votos'!H15)/'Base votos'!R15 -> 0.048872446 | L16: =('Base votos'!H48)/'Base votos'!R48 -> 0.040683182 | M16: =(L16-K16)*100 -> -0.81892644 | N16: =('Base votos'!I15)/'Base votos'!R15 -> 0.14226433 | O16: =('Base votos'!I48)/'Base votos'!R48 -> 0.10242823 | P16: =(O16-N16)*100 -> -3.9836102 | Q16: =('Base votos'!J15)/'Base votos'!R15 -> 0.066056345 | R16: =('Base votos'!J48)/'Base votos'!R48 -> 0.044702277 | S16: =(R16-Q16)*100 -> -2.1354068 | T16: =('Base votos'!K15)/'Base votos'!R15 -> 0.020111113 | U16: =('Base votos'!K48)/'Base votos'!R48 -> 0.063755242 | V16: =(U16-T16)*100 -> 4.3644129 | W16: =('Base votos'!D15+'Base votos'!E15)/'Base votos'!R15 -> 0.60162181 | X16: =('Base votos'!D48+'Base votos'!E48)/'Base votos'!R48 -> 0.61512096 | Y16: =(X16-W16)*100 -> 1.3499152 | Z16: =('Base votos'!H15+'Base votos'!I15+'Base votos'!J15)/'Base votos'!R15 -> 0.25719312 | AA16: =('Base votos'!H48+'Base votos'!I48+'Base votos'!J48)/'Base votos'!R48 -> 0.18781369 | AB16: =(AA16-Z16)*100 -> -6.9379434
... A37: Nacional | B37: =('Base votos'!D36)/'Base votos'!R36 -> 0.44775158 | C37: =('Base votos'!D69)/'Base votos'!R69 -> 0.45814089 | D37: =(C37-B37)*100 -> 1.0389308 | E37: =('Base votos'!E36)/'Base votos'!R36 -> 0.058816103 | F37: =('Base votos'!E69)/'Base votos'!R69 -> 0.062981193 | G37: =(F37-E37)*100 -> 0.41650898 | H37: =('Base votos'!F36)/'Base votos'!R36 -> 0.017705755 | I37: =('Base votos'!F69)/'Base votos'!R69 -> 0.076472676 | J37: =(I37-H37)*100 -> 5.8766921 | K37: =('Base votos'!H36)/'Base votos'!R36 -> 0.17843084 | L37: =('Base votos'!H69)/'Base votos'!R69 -> 0.16161676 | M37: =(L37-K37)*100 -> -1.6814083 | N37: =('Base votos'!I36)/'Base votos'!R36 -> 0.13716828 | O37: =('Base votos'!I69)/'Base votos'!R69 -> 0.095337012 | P37: =(O37-N37)*100 -> -4.1831265 | Q37: =('Base votos'!J36)/'Base votos'!R36 -> 0.027473005 | R37: =('Base votos'!J69)/'Base votos'!R69 -> 0.017564181 | S37: =(R37-Q37)*100 -> -0.99088231 | T37: =('Base votos'!K36)/'Base votos'!R36 -> 0.0168464 | U37: =('Base votos'!K69)/'Base votos'!R69 -> 0.10321369 | V37: =(U37-T37)*100 -> 8.6367291 | W37: =('Base votos'!D36+'Base votos'!E36)/'Base votos'!R36 -> 0.50656769 | X37: =('Base votos'!D69+'Base votos'!E69)/'Base votos'!R69 -> 0.52112208 | Y37: =(X37-W37)*100 -> 1.4554398 | Z37: =('Base votos'!H36+'Base votos'!I36+'Base votos'!J36)/'Base votos'!R36 -> 0.34307212 | AA37: =('Base votos'!H69+'Base votos'!I69+'Base votos'!J69)/'Base votos'!R69 -> 0.27451795 | AB37: =(AA37-Z37)*100 -> -6.855417

Sheet Presidencia - Bloques
A1: Presidencia: bloques como compitieron, participación, nulos, márgenes y cambios de ganador por estado (2018 – 2024)
A2: Bloque = partido solo + sus combinaciones de coalición, tal como compitieron ese año (los nombres cambian entre años; ver encabezados). % sobre el total de votos emitidos. Δ en puntos porcentuales.
B3: Participación | E3: Votos nulos % | H3: Votos emitidos | L3: Bloque de Morena y aliados | O3: Bloque del PAN y aliados | R3: Tercer bloque (PRI en 2018 / MC en 2021-2024) | U3: Margen de victoria (pts) | X3: Bloque ganador y cambios
A4: Estado | B4: 2018 | C4: 2024 | D4: Δ 2024 vs 2018 (pts) | E4: 2018 | F4: 2024 | G4: Δ 2024 vs 2018 (pts) | H4: 2018 | I4: 2024 | J4: Δ 2024 vs 2018 (votos) | K4: Δ 2024 vs 2018 (%) | L4: 2018 (Juntos Haremos Historia (PT-Morena-PES)) | M4: 2024 (Sigamos Haciendo Historia (PVEM-PT-Morena)) | N4: Δ 2024 vs 2018 (pts) | O4: 2018 (Por México al Frente (PAN-PRD-MC)) | P4: 2024 (Fuerza y Corazón por México (PAN-PRI-PRD)) | Q4: Δ 2024 vs 2018 (pts) | R4: 2018 (Todos por México (PRI-PVEM-NA)) | S4: 2024 (MC) | T4: Δ 2024 vs 2018 (pts) | U4: 2018 | V4: 2024 | W4: Δ 2024 vs 2018 (pts) | X4: Ganador 2018 | Y4: Ganador 2024 | Z4: Cambio 2018 → 2024
A5: Aguascalientes | B5: ='Base votos'!R4/'Base votos'!S4 -> 0.59368066 | C5: ='Base votos'!R37/'Base votos'!S37 -> 0.60559637 | D5: =(C5-B5)*100 -> 1.1915704 | E5: ='Base votos'!Q4/'Base votos'!R4 -> 0.026223209 | F5: ='Base votos'!Q37/'Base votos'!R37 -> 0.021321082 | G5: =(F5-E5)*100 -> -0.49021276 | H5: ='Base votos'!R4 -> 561106 | I5: ='Base votos'!R37 -> 666242 | J5: =I5-H5 -> 105136 | K5: =I5/H5-1 -> 0.1873728 | L5: ='Base votos'!U4/'Base votos'!R4 -> 0.39658817 | M5: ='Base votos'!U37/'Base votos'!R37 -> 0.42733121 | N5: =(M5-L5)*100 -> 3.0743043 | O5: ='Base votos'!V4/'Base votos'!R4 -> 0.31899142 | P5: ='Base votos'!V37/'Base votos'!R37 -> 0.45968582 | Q5: =(P5-O5)*100 -> 14.06944 | R5: ='Base votos'!W4/'Base votos'!R4 -> 0.18470485 | S5: ='Base votos'!W37/'Base votos'!R37 -> 0.089303887 | T5: =(S5-R5)*100 -> -9.5400964 | U5: =(MAX('Base votos'!U4:W4)-LARGE('Base votos'!U4:W4,2))/'Base votos'!R4*100 -> 7.7596746 | V5: =(MAX('Base votos'!U37:W37)-LARGE('Base votos'!U37:W37,2))/'Base votos'!R37*100 -> 3.235461 | W5: =(V5-U5) -> -4.5242137 | X5: Morena y aliados | Y5: PAN y aliados | Z5: Morena y aliados → PAN y aliados
A6: Baja California | B6: ='Base votos'!R5/'Base votos'!S5 -> 0.52608611 | C6: ='Base votos'!R38/'Base votos'!S38 -> 0.48723924 | D6: =(C6-B6)*100 -> -3.8846864 | E6: ='Base votos'!Q5/'Base votos'!R5 -> 0.019605512 | F6: ='Base votos'!Q38/'Base votos'!R38 -> 0.020195689 | G6: =(F6-E6)*100 -> 0.059017685 | H6: ='Base votos'!R5 -> 1438422 | I6: ='Base votos'!R38 -> 1560333 | J6: =I6-H6 -> 121911 | K6: =I6/H6-1 -> 0.084753292 | L6: ='Base votos'!U5/'Base votos'!R5 -> 0.63885216 | M6: ='Base votos'!U38/'Base votos'!R38 -> 0.66650709 | N6: =(M6-L6)*100 -> 2.7654927 | O6: ='Base votos'!V5/'Base votos'!R5 -> 0.19153141 | P6: ='Base votos'!V38/'Base votos'!R38 -> 0.21191438 | Q6: =(P6-O6)*100 -> 2.0382966 | R6: ='Base votos'!W5/'Base votos'!R5 -> 0.086361999 | S6: ='Base votos'!W38/'Base votos'!R38 -> 0.099505682 | T6: =(S6-R6)*100 -> 1.3143683 | U6: =(MAX('Base votos'!U5:W5)-LARGE('Base votos'!U5:W5,2))/'Base votos'!R5*100 -> 44.732074 | V6: =(MAX('Base votos'!U38:W38)-LARGE('Base votos'!U38:W38,2))/'Base votos'!R38*100 -> 45.459271 | W6: =(V6-U6) -> 0.7271961 | X6: Morena y aliados | Y6: Morena y aliados | Z6: Se mantiene: Morena y aliados
A7: Baja California Sur | B7: ='Base votos'!R6/'Base votos'!S6 -> 0.58657732 | C7: ='Base votos'!R39/'Base votos'!S39 -> 0.55367536 | D7: =(C7-B7)*100 -> -3.2901963 | E7: ='Base votos'!Q6/'Base votos'!R6 -> 0.021938802 | F7: ='Base votos'!Q39/'Base votos'!R39 -> 0.022167727 | G7: =(F7-E7)*100 -> 0.022892422 | H7: ='Base votos'!R6 -> 302888 | I7: ='Base votos'!R39 -> 340089 | J7: =I7-H7 -> 37201 | K7: =I7/H7-1 -> 0.12282098 | L7: ='Base votos'!U6/'Base votos'!R6 -> 0.63997913 | M7: ='Base votos'!U39/'Base votos'!R39 -> 0.59139225 | N7: =(M7-L7)*100 -> -4.8586881 | O7: ='Base votos'!V6/'Base votos'!R6 -> 0.18750825 | P7: ='Base votos'!V39/'Base votos'!R39 -> 0.29738098 | Q7: =(P7-O7)*100 -> 10.987273 | R7: ='Base votos'!W6/'Base votos'!R6 -> 0.093110325 | S7: ='Base votos'!W39/'Base votos'!R39 -> 0.087697632 | T7: =(S7-R7)*100 -> -0.54126925 | U7: =(MAX('Base votos'!U6:W6)-LARGE('Base votos'!U6:W6,2))/'Base votos'!R6*100 -> 45.247088 | V7: =(MAX('Base votos'!U39:W39)-LARGE('Base votos'!U39:W39,2))/'Base votos'!R39*100 -> 29.401127 | W7: =(V7-U7) -> -15.845961 | X7: Morena y aliados | Y7: Morena y aliados | Z7: Se mantiene: Morena y aliados
A8: Campeche | B8: ='Base votos'!R7/'Base votos'!S7 -> 0.69978534 | C8: ='Base votos'!R40/'Base votos'!S40 -> 0.64611133 | D8: =(C8-B8)*100 -> -5.3674007 | E8: ='Base votos'!Q7/'Base votos'!R7 -> 0.026104056 | F8: ='Base votos'!Q40/'Base votos'!R40 -> 0.021307245 | G8: =(F8-E8)*100 -> -0.47968107 | H8: ='Base votos'!R7 -> 449547 | I8: ='Base votos'!R40 -> 449143 | J8: =I8-H8 -> -404 | K8: =I8/H8-1 -> -0.00089868245 | L8: ='Base votos'!U7/'Base votos'!R7 -> 0.61230973 | M8: ='Base votos'!U40/'Base votos'!R40 -> 0.61297849 | N8: =(M8-L8)*100 -> 0.066876948 | O8: ='Base votos'!V7/'Base votos'!R7 -> 0.12104852 | P8: ='Base votos'!V40/'Base votos'!R40 -> 0.15484155 | Q8: =(P8-O8)*100 -> 3.3793032 | R8: ='Base votos'!W7/'Base votos'!R7 -> 0.21484739 | S8: ='Base votos'!W40/'Base votos'!R40 -> 0.20991087 | T8: =(S8-R8)*100 -> -0.49365161 | U8: =(MAX('Base votos'!U7:W7)-LARGE('Base votos'!U7:W7,2))/'Base votos'!R7*100 -> 39.746233 | V8: =(MAX('Base votos'!U40:W40)-LARGE('Base votos'!U40:W40,2))/'Base votos'!R40*100 -> 40.306762 | W8: =(V8-U8) -> 0.56052856 | X8: Morena y aliados | Y8: Morena y aliados | Z8: Se mantiene: Morena y aliados
A9: Coahuila | B9: ='Base votos'!R8/'Base votos'!S8 -> 0.63591138 | C9: ='Base votos'!R41/'Base votos'!S41 -> 0.65785324 | D9: =(C9-B9)*100 -> 2.1941866 | E9: ='Base votos'!Q8/'Base votos'!R8 -> 0.017762586 | F9: ='Base votos'!Q41/'Base votos'!R41 -> 0.019515216 | G9: =(F9-E9)*100 -> 0.17526302 | H9: ='Base votos'!R8 -> 1371816 | I9: ='Base votos'!R41 -> 1588709 | J9: =I9-H9 -> 216893 | K9: =I9/H9-1 -> 0.15810648 | L9: ='Base votos'!U8/'Base votos'!R8 -> 0.44420097 | M9: ='Base votos'!U41/'Base votos'!R41 -> 0.537189 | N9: =(M9-L9)*100 -> 9.2988029 | O9: ='Base votos'!V8/'Base votos'!R8 -> 0.22422103 | P9: ='Base votos'!V41/'Base votos'!R41 -> 0.38849657 | Q9: =(P9-O9)*100 -> 16.427554 | R9: ='Base votos'!W8/'Base votos'!R8 -> 0.26117132 | S9: ='Base votos'!W41/'Base votos'!R41 -> 0.054041993 | T9: =(S9-R9)*100 -> -20.712933 | U9: =(MAX('Base votos'!U8:W8)-LARGE('Base votos'!U8:W8,2))/'Base votos'!R8*100 -> 18.302965 | V9: =(MAX('Base votos'!U41:W41)-LARGE('Base votos'!U41:W41,2))/'Base votos'!R41*100 -> 14.869243 | W9: =(V9-U9) -> -3.4337219 | X9: Morena y aliados | Y9: Morena y aliados | Z9: Se mantiene: Morena y aliados
A10: Colima | B10: ='Base votos'!R9/'Base votos'!S9 -> 0.64131735 | C10: ='Base votos'!R42/'Base votos'!S42 -> 0.5901331 | D10: =(C10-B10)*100 -> -5.1184249 | E10: ='Base votos'!Q9/'Base votos'!R9 -> 0.026566288 | F10: ='Base votos'!Q42/'Base votos'!R42 -> 0.020962657 | G10: =(F10-E10)*100 -> -0.56036316 | H10: ='Base votos'!R9 -> 341109 | I10: ='Base votos'!R42 -> 345710 | J10: =I10-H10 -> 4601 | K10: =I10/H10-1 -> 0.013488357 | L10: ='Base votos'!U9/'Base votos'!R9 -> 0.57845439 | M10: ='Base votos'!U42/'Base votos'!R42 -> 0.54407741 | N10: =(M10-L10)*100 -> -3.4376988 | O10: ='Base votos'!V9/'Base votos'!R9 -> 0.16542513 | P10: ='Base votos'!V42/'Base votos'!R42 -> 0.29961528 | Q10: =(P10-O10)*100 -> 13.419016 | R10: ='Base votos'!W9/'Base votos'!R9 -> 0.18177181 | S10: ='Base votos'!W42/'Base votos'!R42 -> 0.13332562 | T10: =(S10-R10)*100 -> -4.8446189 | U10: =(MAX('Base votos'!U9:W9)-LARGE('Base votos'!U9:W9,2))/'Base votos'!R9*100 -> 39.668259 | V10: =(MAX('Base votos'!U42:W42)-LARGE('Base votos'!U42:W42,2))/'Base votos'!R42*100 -> 24.446212 | W10: =(V10-U10) -> -15.222046 | X10: Morena y aliados | Y10: Morena y aliados | Z10: Se mantiene: Morena y aliados
A11: Chiapas | B11: ='Base votos'!R10/'Base votos'!S10 -> 0.69270047 | C11: ='Base votos'!R43/'Base votos'!S43 -> 0.62633599 | D11: =(C11-B11)*100 -> -6.6364476 | E11: ='Base votos'!Q10/'Base votos'!R10 -> 0.056515573 | F11: ='Base votos'!Q43/'Base votos'!R43 -> 0.042579777 | G11: =(F11-E11)*100 -> -1.3935796 | H11: ='Base votos'!R10 -> 2425650 | I11: ='Base votos'!R43 -> 2472958 | J11: =I11-H11 -> 47308 | K11: =I11/H11-1 -> 0.019503226 | L11: ='Base votos'!U10/'Base votos'!R10 -> 0.61249521 | M11: ='Base votos'!U43/'Base votos'!R43 -> 0.71551721 | N11: =(M11-L11)*100 -> 10.3022 | O11: ='Base votos'!V10/'Base votos'!R10 -> 0.081675839 | P11: ='Base votos'!V43/'Base votos'!R43 -> 0.1669442 | Q11: =(P11-O11)*100 -> 8.5268363 | R11: ='Base votos'!W10/'Base votos'!R10 -> 0.23204626 | S11: ='Base votos'!W43/'Base votos'!R43 -> 0.07404129 | T11: =(S11-R11)*100 -> -15.800497 | U11: =(MAX('Base votos'!U10:W10)-LARGE('Base votos'!U10:W10,2))/'Base votos'!R10*100 -> 38.044895 | V11: =(MAX('Base votos'!U43:W43)-LARGE('Base votos'!U43:W43,2))/'Base votos'!R43*100 -> 54.8573 | W11: =(V11-U11) -> 16.812405 | X11: Morena y aliados | Y11: Morena y aliados | Z11: Se mantiene: Morena y aliados
A12: Chihuahua | B12: ='Base votos'!R11/'Base votos'!S11 -> 0.54446855 | C12: ='Base votos'!R44/'Base votos'!S44 -> 0.5322307 | D12: =(C12-B12)*100 -> -1.2237848 | E12: ='Base votos'!Q11/'Base votos'!R11 -> 0.032679358 | F12: ='Base votos'!Q44/'Base votos'!R44 -> 0.024161328 | G12: =(F12-E12)*100 -> -0.85180305 | H12: ='Base votos'!R11 -> 1494705 | I12: ='Base votos'!R44 -> 1644653 | J12: =I12-H12 -> 149948 | K12: =I12/H12-1 -> 0.10031946 | L12: ='Base votos'!U11/'Base votos'!R11 -> 0.43062143 | M12: ='Base votos'!U44/'Base votos'!R44 -> 0.53863581 | N12: =(M12-L12)*100 -> 10.801438 | O12: ='Base votos'!V11/'Base votos'!R11 -> 0.28495188 | P12: ='Base votos'!V44/'Base votos'!R44 -> 0.34030887 | Q12: =(P12-O12)*100 -> 5.5356987 | R12: ='Base votos'!W11/'Base votos'!R11 -> 0.16105185 | S12: ='Base votos'!W44/'Base votos'!R44 -> 0.095507685 | T12: =(S12-R12)*100 -> -6.5544162 | U12: =(MAX('Base votos'!U11:W11)-LARGE('Base votos'!U11:W11,2))/'Base votos'!R11*100 -> 14.566955 | V12: =(MAX('Base votos'!U44:W44)-LARGE('Base votos'!U44:W44,2))/'Base votos'!R44*100 -> 19.832694 | W12: =(V12-U12) -> 5.2657395 | X12: Morena y aliados | Y12: Morena y aliados | Z12: Se mantiene: Morena y aliados
A13: Ciudad de México | B13: ='Base votos'!R12/'Base votos'!S12 -> 0.70613038 | C13: ='Base votos'!R45/'Base votos'!S45 -> 0.70346545 | D13: =(C13-B13)*100 -> -0.2664936 | E13: ='Base votos'!Q12/'Base votos'!R12 -> 0.020641643 | F13: ='Base votos'!Q45/'Base votos'!R45 -> 0.017352138 | G13: =(F13-E13)*100 -> -0.32895053 | H13: ='Base votos'!R12 -> 5405868 | I13: ='Base votos'!R45 -> 5607551 | J13: =I13-H13 -> 201683 | K13: =I13/H13-1 -> 0.037308162 | L13: ='Base votos'!U12/'Base votos'!R12 -> 0.57686906 | M13: ='Base votos'!U45/'Base votos'!R45 -> 0.552008 | N13: =(M13-L13)*100 -> -2.4861064 | O13: ='Base votos'!V12/'Base votos'!R12 -> 0.23911479 | P13: ='Base votos'!V45/'Base votos'!R45 -> 0.34545419 | Q13: =(P13-O13)*100 -> 10.63394 | R13: ='Base votos'!W12/'Base votos'!R12 -> 0.12062318 | S13: ='Base votos'!W45/'Base votos'!R45 -> 0.08345176 | T13: =(S13-R13)*100 -> -3.7171422 | U13: =(MAX('Base votos'!U12:W12)-LARGE('Base votos'!U12:W12,2))/'Base votos'!R12*100 -> 33.775427 | V13: =(MAX('Base votos'!U45:W45)-LARGE('Base votos'!U45:W45,2))/'Base votos'!R45*100 -> 20.655381 | W13: =(V13-U13) -> -13.120046 | X13: Morena y aliados | Y13: Morena y aliados | Z13: Se mantiene: Morena y aliados
A14: Durango | B14: ='Base votos'!R13/'Base votos'!S13 -> 0.57122359 | C14: ='Base votos'!R46/'Base votos'!S46 -> 0.55547592 | D14: =(C14-B14)*100 -> -1.5747673 | E14: ='Base votos'!Q13/'Base votos'!R13 -> 0.022880819 | F14: ='Base votos'!Q46/'Base votos'!R46 -> 0.021264331 | G14: =(F14-E14)*100 -> -0.16164879 | H14: ='Base votos'!R13 -> 733715 | I14: ='Base votos'!R46 -> 778910 | J14: =I14-H14 -> 45195 | K14: =I14/H14-1 -> 0.061597487 | L14: ='Base votos'!U13/'Base votos'!R13 -> 0.46452505 | M14: ='Base votos'!U46/'Base votos'!R46 -> 0.58445392 | N14: =(M14-L14)*100 -> 11.992886 | O14: ='Base votos'!V13/'Base votos'!R13 -> 0.25615805 | P14: ='Base votos'!V46/'Base votos'!R46 -> 0.32132467 | Q14: =(P14-O14)*100 -> 6.5166627 | R14: ='Base votos'!W13/'Base votos'!R13 -> 0.19256932 | S14: ='Base votos'!W46/'Base votos'!R46 -> 0.072060957 | T14: =(S14-R14)*100 -> -12.050836 | U14: =(MAX('Base votos'!U13:W13)-LARGE('Base votos'!U13:W13,2))/'Base votos'!R13*100 -> 20.836701 | V14: =(MAX('Base votos'!U46:W46)-LARGE('Base votos'!U46:W46,2))/'Base votos'!R46*100 -> 26.312924 | W14: =(V14-U14) -> 5.4762236 | X14: Morena y aliados | Y14: Morena y aliados | Z14: Se mantiene: Morena y aliados
A15: Guanajuato | B15: ='Base votos'!R14/'Base votos'!S14 -> 0.53196919 | C15: ='Base votos'!R47/'Base votos'!S47 -> 0.56962358 | D15: =(C15-B15)*100 -> 3.7654387 | E15: ='Base votos'!Q14/'Base votos'!R14 -> 0.029777115 | F15: ='Base votos'!Q47/'Base votos'!R47 -> 0.020683616 | G15: =(F15-E15)*100 -> -0.90934984 | H15: ='Base votos'!R14 -> 2325007 | I15: ='Base votos'!R47 -> 2759092 | J15: =I15-H15 -> 434085 | K15: =I15/H15-1 -> 0.18670266 | L15: ='Base votos'!U14/'Base votos'!R14 -> 0.30418059 | M15: ='Base votos'!U47/'Base votos'!R47 -> 0.47215026 | N15: =(M15-L15)*100 -> 16.796967 | O15: ='Base votos'!V14/'Base votos'!R14 -> 0.40435706 | P15: ='Base votos'!V47/'Base votos'!R47 -> 0.39988735 | Q15: =(P15-O15)*100 -> -0.44697079 | R15: ='Base votos'!W14/'Base votos'!R14 -> 0.16416811 | S15: ='Base votos'!W47/'Base votos'!R47 -> 0.10560684 | T15: =(S15-R15)*100 -> -5.8561263 | U15: =(MAX('Base votos'!U14:W14)-LARGE('Base votos'!U14:W14,2))/'Base votos'!R14*100 -> 10.017647 | V15: =(MAX('Base votos'!U47:W47)-LARGE('Base votos'!U47:W47,2))/'Base votos'!R47*100 -> 7.2262904 | W15: =(V15-U15) -> -2.7913569 | X15: PAN y aliados | Y15: Morena y aliados | Z15: PAN y aliados → Morena y aliados
A16: Guerrero | B16: ='Base votos'!R15/'Base votos'!S15 -> 0.64214925 | C16: ='Base votos'!R48/'Base votos'!S48 -> 0.58454568 | D16: =(C16-B16)*100 -> -5.7603568 | E16: ='Base votos'!Q15/'Base votos'!R15 -> 0.041018189 | F16: ='Base votos'!Q48/'Base votos'!R48 -> 0.030881233 | G16: =(F16-E16)*100 -> -1.0136956 | H16: ='Base votos'!R15 -> 1613138 | I16: ='Base votos'!R48 -> 1550100 | J16: =I16-H16 -> -63038 | K16: =I16/H16-1 -> -0.039077872 | L16: ='Base votos'!U15/'Base votos'!R15 -> 0.63116919 | M16: ='Base votos'!U48/'Base votos'!R48 -> 0.71662731 | N16: =(M16-L16)*100 -> 8.5458127 | O16: ='Base votos'!V15/'Base votos'!R15 -> 0.1350399 | P16: ='Base votos'!V48/'Base votos'!R48 -> 0.18781369 | Q16: =(P16-O16)*100 -> 5.2773786 | R16: ='Base votos'!W15/'Base votos'!R15 -> 0.17716959 | S16: ='Base votos'!W48/'Base votos'!R48 -> 0.063755242 | T16: =(S16-R16)*100 -> -11.341435 | U16: =(MAX('Base votos'!U15:W15)-LARGE('Base votos'!U15:W15,2))/'Base votos'!R15*100 -> 45.39996 | V16: =(MAX('Base votos'!U48:W48)-LARGE('Base votos'!U48:W48,2))/'Base votos'!R48*100 -> 52.881362 | W16: =(V16-U16) -> 7.4814029 | X16: Morena y aliados | Y16: Morena y aliados | Z16: Se mantiene: Morena y aliados
... A37: Nacional | B37: ='Base votos'!R36/'Base votos'!S36 -> 0.63515342 | C37: ='Base votos'!R69/'Base votos'!S69 -> 0.61049861 | D37: =(C37-B37)*100 -> -2.4654812 | E37: ='Base votos'!Q36/'Base votos'!R36 -> 0.027752791 | F37: ='Base votos'!Q69/'Base votos'!R69 -> 0.023291021 | G37: =(F37-E37)*100 -> -0.44617702 | H37: ='Base votos'!R36 -> 56611027 | I37: ='Base votos'!R69 -> 60115184 | J37: =I37-H37 -> 3504157 | K37: =I37/H37-1 -> 0.061898842 | L37: ='Base votos'!U36/'Base votos'!R36 -> 0.5319367 | M37: ='Base votos'!U69/'Base votos'!R69 -> 0.59759476 | N37: =(M37-L37)*100 -> 6.5658059 | O37: ='Base votos'!V36/'Base votos'!R36 -> 0.22275024 | P37: ='Base votos'!V69/'Base votos'!R69 -> 0.27451795 | Q37: =(P37-O37)*100 -> 5.1767706 | R37: ='Base votos'!W36/'Base votos'!R36 -> 0.16409971 | S37: ='Base votos'!W69/'Base votos'!R69 -> 0.10321369 | T37: =(S37-R37)*100 -> -6.0886017 | U37: =(MAX('Base votos'!U36:W36)-LARGE('Base votos'!U36:W36,2))/'Base votos'!R36*100 -> 30.918646 | V37: =(MAX('Base votos'!U69:W69)-LARGE('Base votos'!U69:W69,2))/'Base votos'!R69*100 -> 32.307681 | W37: =(V37-U37) -> 1.3890353 | X37: Morena y aliados | Y37: Morena y aliados | Z37: Se mantiene: Morena y aliados

Sheet Diputaciones - Partidos
A1: Diputaciones: voto por partido y cambio por estado (2018 – 2021 – 2024)
A2: % sobre el total de votos emitidos. El voto de coalición se reparte entre sus partidos (ver Metodología). Las columnas Δ están en puntos porcentuales: verde = sube, rojo = baja.
B3: Morena | H3: PT | N3: PVEM | T3: PAN | Z3: PRI | AF3: PRD | AL3: MC | AR3: Morena + PT | AX3: PAN + PRI + PRD
A4: Estado | B4: 2018 | C4: 2021 | D4: 2024 | E4: Δ 2021 vs 2018 (pts) | F4: Δ 2024 vs 2021 (pts) | G4: Δ 2024 vs 2018 (pts) | H4: 2018 | I4: 2021 | J4: 2024 | K4: Δ 2021 vs 2018 (pts) | L4: Δ 2024 vs 2021 (pts) | M4: Δ 2024 vs 2018 (pts) | N4: 2018 | O4: 2021 | P4: 2024 | Q4: Δ 2021 vs 2018 (pts) | R4: Δ 2024 vs 2021 (pts) | S4: Δ 2024 vs 2018 (pts) | T4: 2018 | U4: 2021 | V4: 2024 | W4: Δ 2021 vs 2018 (pts) | X4: Δ 2024 vs 2021 (pts) | Y4: Δ 2024 vs 2018 (pts) | Z4: 2018 | AA4: 2021 | AB4: 2024 | AC4: Δ 2021 vs 2018 (pts) | AD4: Δ 2024 vs 2021 (pts) | AE4: Δ 2024 vs 2018 (pts) | AF4: 2018 | AG4: 2021 | AH4: 2024 | AI4: Δ 2021 vs 2018 (pts) | AJ4: Δ 2024 vs 2021 (pts) | AK4: Δ 2024 vs 2018 (pts) | AL4: 2018 | AM4: 2021 | AN4: 2024 | AO4: Δ 2021 vs 2018 (pts) | AP4: Δ 2024 vs 2021 (pts) | AQ4: Δ 2024 vs 2018 (pts) | AR4: 2018 | AS4: 2021 | AT4: 2024 | AU4: Δ 2021 vs 2018 (pts) | AV4: Δ 2024 vs 2021 (pts) | AW4: Δ 2024 vs 2018 (pts) | AX4: 2018 | AY4: 2021 | AZ4: 2024 | BA4: Δ 2021 vs 2018 (pts) | BB4: Δ 2024 vs 2021 (pts) | BC4: Δ 2024 vs 2018 (pts)
A5: Aguascalientes | B5: =('Base votos'!D70)/'Base votos'!R70 -> 0.26516574 | C5: =('Base votos'!D103)/'Base votos'!R103 -> 0.25056216 | D5: =('Base votos'!D136)/'Base votos'!R136 -> 0.30921912 | E5: =(C5-B5)*100 -> -1.460358 | F5: =(D5-C5)*100 -> 5.8656961 | G5: =(D5-B5)*100 -> 4.4053381 | H5: =('Base votos'!E70)/'Base votos'!R70 -> 0.030278472 | I5: =('Base votos'!E103)/'Base votos'!R103 -> 0.023285897 | J5: =('Base votos'!E136)/'Base votos'!R136 -> 0.026530252 | K5: =(I5-H5)*100 -> -0.69925755 | L5: =(J5-I5)*100 -> 0.32443552 | M5: =(J5-H5)*100 -> -0.37482203 | N5: =('Base votos'!F70)/'Base votos'!R70 -> 0.043766318 | O5: =('Base votos'!F103)/'Base votos'!R103 -> 0.03571373 | P5: =('Base votos'!F136)/'Base votos'!R136 -> 0.03684055 | Q5: =(O5-N5)*100 -> -0.80525885 | R5: =(P5-O5)*100 -> 0.11268205 | S5: =(P5-N5)*100 -> -0.6925768 | T5: =('Base votos'!H70)/'Base votos'!R70 -> 0.32880624 | U5: =('Base votos'!H103)/'Base votos'!R103 -> 0.44601508 | V5: =('Base votos'!H136)/'Base votos'!R136 -> 0.4135951 | W5: =(U5-T5)*100 -> 11.720884 | X5: =(V5-U5)*100 -> -3.2419981 | Y5: =(V5-T5)*100 -> 8.4788861 | Z5: =('Base votos'!I70)/'Base votos'!R70 -> 0.18796372 | AA5: =('Base votos'!I103)/'Base votos'!R103 -> 0.090638179 | AB5: =('Base votos'!I136)/'Base votos'!R136 -> 0.075669766 | AC5: =(AA5-Z5)*100 -> -9.7325545 | AD5: =(AB5-AA5)*100 -> -1.4968413 | AE5: =(AB5-Z5)*100 -> -11.229396 | AF5: =('Base votos'!J70)/'Base votos'!R70 -> 0.023252429 | AG5: =('Base votos'!J103)/'Base votos'!R103 -> 0.027726771 | AH5: =('Base votos'!J136)/'Base votos'!R136 -> 0.024873539 | AI5: =(AG5-AF5)*100 -> 0.44743415 | AJ5: =(AH5-AG5)*100 -> -0.28532319 | AK5: =(AH5-AF5)*100 -> 0.16211096 | AL5: =('Base votos'!K70)/'Base votos'!R70 -> 0.0218005 | AM5: =('Base votos'!K103)/'Base votos'!R103 -> 0.038827983 | AN5: =('Base votos'!K136)/'Base votos'!R136 -> 0.080617065 | AO5: =(AM5-AL5)*100 -> 1.7027483 | AP5: =(AN5-AM5)*100 -> 4.1789082 | AQ5: =(AN5-AL5)*100 -> 5.8816565 | AR5: =('Base votos'!D70+'Base votos'!E70)/'Base votos'!R70 -> 0.29544421 | AS5: =('Base votos'!D103+'Base votos'!E103)/'Base votos'!R103 -> 0.27384806 | AT5: =('Base votos'!D136+'Base votos'!E136)/'Base votos'!R136 -> 0.33574937 | AU5: =(AS5-AR5)*100 -> -2.1596156 | AV5: =(AT5-AS5)*100 -> 6.1901316 | AW5: =(AT5-AR5)*100 -> 4.030516 | AX5: =('Base votos'!H70+'Base votos'!I70+'Base votos'!J70)/'Base votos'!R70 -> 0.54002239 | AY5: =('Base votos'!H103+'Base votos'!I103+'Base votos'!J103)/'Base votos'!R103 -> 0.56438003 | AZ5: =('Base votos'!H136+'Base votos'!I136+'Base votos'!J136)/'Base votos'!R136 -> 0.5141384 | BA5: =(AY5-AX5)*100 -> 2.4357638 | BB5: =(AZ5-AY5)*100 -> -5.0241626 | BC5: =(AZ5-AX5)*100 -> -2.5883987
A6: Baja California | B6: =('Base votos'!D71)/'Base votos'!R71 -> 0.5055354 | C6: =('Base votos'!D104)/'Base votos'!R104 -> 0.44378125 | D6: =('Base votos'!D137)/'Base votos'!R137 -> 0.51868319 | E6: =(C6-B6)*100 -> -6.1754152 | F6: =(D6-C6)*100 -> 7.4901949 | G6: =(D6-B6)*100 -> 1.3147796 | H6: =('Base votos'!E71)/'Base votos'!R71 -> 0.04933539 | I6: =('Base votos'!E104)/'Base votos'!R104 -> 0.023817304 | J6: =('Base votos'!E137)/'Base votos'!R137 -> 0.055387963 | K6: =(I6-H6)*100 -> -2.5518086 | L6: =(J6-I6)*100 -> 3.1570659 | M6: =(J6-H6)*100 -> 0.6052573 | N6: =('Base votos'!F71)/'Base votos'!R71 -> 0.034624996 | O6: =('Base votos'!F104)/'Base votos'!R104 -> 0.024517106 | P6: =('Base votos'!F137)/'Base votos'!R137 -> 0.065206243 | Q6: =(O6-N6)*100 -> -1.010789 | R6: =(P6-O6)*100 -> 4.0689137 | S6: =(P6-N6)*100 -> 3.0581247 | T6: =('Base votos'!H71)/'Base votos'!R71 -> 0.18997869 | U6: =('Base votos'!H104)/'Base votos'!R104 -> 0.14782024 | V6: =('Base votos'!H137)/'Base votos'!R137 -> 0.15474748 | W6: =(U6-T6)*100 -> -4.2158451 | X6: =(V6-U6)*100 -> 0.69272377 | Y6: =(V6-T6)*100 -> -3.5231213 | Z6: =('Base votos'!I71)/'Base votos'!R71 -> 0.090780799 | AA6: =('Base votos'!I104)/'Base votos'!R104 -> 0.056663476 | AB6: =('Base votos'!I137)/'Base votos'!R137 -> 0.049829198 | AC6: =(AA6-Z6)*100 -> -3.4117322 | AD6: =(AB6-AA6)*100 -> -0.68342783 | AE6: =(AB6-Z6)*100 -> -4.0951601 | AF6: =('Base votos'!J71)/'Base votos'!R71 -> 0.016527404 | AG6: =('Base votos'!J104)/'Base votos'!R104 -> 0.013763661 | AH6: =('Base votos'!J137)/'Base votos'!R137 -> 0.012160041 | AI6: =(AG6-AF6)*100 -> -0.27637433 | AJ6: =(AH6-AG6)*100 -> -0.160362 | AK6: =(AH6-AF6)*100 -> -0.43673633 | AL6: =('Base votos'!K71)/'Base votos'!R71 -> 0.027022975 | AM6: =('Base votos'!K104)/'Base votos'!R104 -> 0.046341843 | AN6: =('Base votos'!K137)/'Base votos'!R137 -> 0.090360723 | AO6: =(AM6-AL6)*100 -> 1.9318868 | AP6: =(AN6-AM6)*100 -> 4.401888 | AQ6: =(AN6-AL6)*100 -> 6.3337748 | AR6: =('Base votos'!D71+'Base votos'!E71)/'Base votos'!R71 -> 0.55487079 | AS6: =('Base votos'!D104+'Base votos'!E104)/'Base votos'!R104 -> 0.46759855 | AT6: =('Base votos'!D137+'Base votos'!E137)/'Base votos'!R137 -> 0.57407116 | AU6: =(AS6-AR6)*100 -> -8.7272239 | AV6: =(AT6-AS6)*100 -> 10.647261 | AW6: =(AT6-AR6)*100 -> 1.9200369 | AX6: =('Base votos'!H71+'Base votos'!I71+'Base votos'!J71)/'Base votos'!R71 -> 0.2972869 | AY6: =('Base votos'!H104+'Base votos'!I104+'Base votos'!J104)/'Base votos'!R104 -> 0.21824738 | AZ6: =('Base votos'!H137+'Base votos'!I137+'Base votos'!J137)/'Base votos'!R137 -> 0.21673672 | BA6: =(AY6-AX6)*100 -> -7.9039516 | BB6: =(AZ6-AY6)*100 -> -0.15106606 | BC6: =(AZ6-AX6)*100 -> -8.0550177
